#VRML_SIM R2025a utf8

EXTERNPROTO "https://raw.githubusercontent.com/cyberbotics/webots/R2025a/projects/objects/backgrounds/protos/TexturedBackground.proto"
EXTERNPROTO "https://raw.githubusercontent.com/cyberbotics/webots/R2025a/projects/objects/backgrounds/protos/TexturedBackgroundLight.proto"
EXTERNPROTO "https://raw.githubusercontent.com/cyberbotics/webots/R2025a/projects/objects/factory/containers/protos/WoodenBox.proto"
EXTERNPROTO "https://raw.githubusercontent.com/cyberbotics/webots/R2025a/projects/objects/floors/protos/Floor.proto"
EXTERNPROTO "https://raw.githubusercontent.com/cyberbotics/webots/R2025a/projects/appearances/protos/OldSteel.proto"

WorldInfo {
  basicTimeStep 16
}
Viewpoint {
  orientation 0.1682948084101944 0.024252671764647914 -0.9854383112983036 2.859442733361265
  position 0.4601850004728663 0.1038206526331169 0.23246677316203485
}
TexturedBackground {
}
TexturedBackgroundLight {
}
Floor {
  size 1 1
}
WoodenBox {
  translation -0.316289 -0.396806 0.05
  rotation 0 0 1 1.77369
  size 0.1 0.1 0.1
}
WoodenBox {
  translation 0.165934 0.220885 0.05
  rotation 0 0 1 1.309
  name "wooden box(2)"
  size 0.1 0.1 0.1
}
WoodenBox {
  translation 0.229083 -0.34108 0.05
  rotation 0 0 1 0.438514
  name "wooden box(1)"
  size 0.1 0.1 0.1
}
Solid {
  translation -0.5 0 0.05
  children [
    DEF WALL_SEG Shape {
      appearance OldSteel {
      }
      geometry Box {
        size 0.05 1 0.1
      }
    }
  ]
  name "wall1"
  boundingObject USE WALL_SEG
}
Solid {
  translation 0 0.5 0.05
  rotation 0 0 1 1.5708
  children [
    USE WALL_SEG
  ]
  name "wall2"
  boundingObject USE WALL_SEG
}
Solid {
  translation 0.5 0 0.05
  children [
    USE WALL_SEG
  ]
  name "wall3"
  boundingObject USE WALL_SEG
}
Solid {
  translation 0 -0.5 0.05
  rotation 0 0 1 1.5708
  children [
    USE WALL_SEG
  ]
  name "wall4"
  boundingObject USE WALL_SEG
}
Robot {
  translation 0 0 0.04
  children [
    DEF _WHEELER_BODY Shape {
      appearance Appearance {
        material Material {
          diffuseColor 0.878431 0.105882 0.141176
        }
      }
      geometry Box {
        size 0.2 0.1 0.05
      }
    }
    DEF _WHEEL_JOINT HingeJoint {
      jointParameters HingeJointParameters {
        axis 0 1 0
        anchor 0.05 0.06 0
      }
      device [
        RotationalMotor {
          name "wheel1"
        }
      ]
      endPoint DEF _WHEEL Solid {
        translation 0.05 0.06 0
        rotation 1 0 0 1.5708
        children [
          DEF _WHEEL_SHAPE Shape {
            appearance Appearance {
              material Material {
                diffuseColor 0.2 0.819608 0.478431
              }
            }
            geometry Cylinder {
              height 0.02
              radius 0.04
            }
          }
        ]
        boundingObject USE _WHEEL_SHAPE
        physics Physics {
        }
      }
    }
    HingeJoint {
      jointParameters HingeJointParameters {
        axis 0 1 0
        anchor 0.05 -0.06 0
      }
      device [
        RotationalMotor {
          name "wheel2"
        }
      ]
      endPoint Solid {
        translation 0.05 -0.06 0
        rotation 1 0 0 1.5708
        children [
          USE _WHEEL_SHAPE
        ]
        name "solid(1)"
        boundingObject USE _WHEEL_SHAPE
        physics Physics {
        }
      }
    }
    HingeJoint {
      jointParameters HingeJointParameters {
        axis 0 1 0
        anchor -0.05 0.06 0
      }
      device [
        RotationalMotor {
          name "wheel3"
        }
      ]
      endPoint Solid {
        translation -0.05 0.06 0
        rotation 1 0 0 1.5708
        children [
          USE _WHEEL_SHAPE
        ]
        name "solid(2)"
        boundingObject USE _WHEEL_SHAPE
        physics Physics {
        }
      }
    }
    HingeJoint {
      jointParameters HingeJointParameters {
        axis 0 1 0
        anchor -0.05 -0.06 0
      }
      device [
        RotationalMotor {
          name "wheel4"
        }
      ]
      endPoint Solid {
        translation -0.05 -0.06 0
        rotation 1 0 0 1.5708
        children [
          USE _WHEEL_SHAPE
        ]
        name "solid(3)"
        boundingObject USE _WHEEL_SHAPE
        physics Physics {
        }
      }
    }
    DistanceSensor {
      translation 0.1 0.03 0
      rotation 0 0 1 0.3
      children [
        DEF _WHEELER_SENSOR Shape {
          appearance Appearance {
            material Material {
              diffuseColor 0.207843 0.517647 0.894118
            }
          }
          geometry Box {
            size 0.01 0.01 0.01
          }
        }
      ]
    }
    DistanceSensor {
      translation 0.1 -0.03 0
      rotation 0 0 1 -0.3
      children [
        USE _WHEELER_SENSOR
      ]
      name "distance sensor(1)"
    }
  ]
  boundingObject USE _WHEELER_BODY
  physics Physics {
  }
}
